Workbook

Sheet Summary
B2: Report Summary
B4: Report Period | C4: =HSummary!E2 -> 01 Feb 2026 - 28 Feb 2026
B5: Res id | C5: =HSummary!F2 -> 20523448
B6: MID | C6: =HSummary!G2 -> 92707
B7: Legal Entity | C7: =HSummary!H2 -> Manaswini Food Private Limited
B8: Res Name | C8: =HSummary!I2 -> Purnabramha Aurangabad
B9: Address | C9: =HSummary!J2 -> 1st floor,Pune, Aurangabad, Maharashtra
B10: PAN | C10: =HSummary!K2 -> AAKCM0381K
B11: GSTIN | C11: =HSummary!L2 -> 27AAKCM0381K1Z7
B12: TAN Number | C12: =HSummary!M2
B13: Pay-out cycle | C13: =HSummary!N2 -> Weekly (Every Wednesday)
B14: Zomato GSTIN - TCS | C14: =HSummary!O2 -> 27AADCD4946L1CL
B15: Zomato GSTIN - Regular | C15: =HSummary!P2 -> 27AADCD4946L1ZA
B16: Total Orders (Delivered + Cancelled/ Rejected) | C16: ='Payout Breakup'!F4 -> 151
B17: Net Pay-out (Settled + Unsettled) | C17: ='Payout Breakup'!F56 -> 47043.51
B18: Bank UTR | C18: =IF(RIGHT(HSummary!S2,1)=",",LEFT(HSummary!S2,LEN(HSummary!S2)-1),HSummary!S2) -> CITIN26625847955,CITIN26617354846,CITIN26620176758,CITIN26622782803
B22: Report Detailed Breakdown
B23: This report comprises the following detailed tabs regarding your pay-out:
B24: Tab Name | C24: Description
B25: Pay-out Breakup | C25: Breakup of your total earnings during this report period
B26: Distance Based Summary | C26: Summary of order level deductions by distance buckets
B27: Order Level | C27: Detailed view of your order level earnings, deductions, pay-outs and UTRs for settled orders.
B28: Addition/Deductions Details | C28: Summarized view on : 1. Res id level additions like 194 H, etc 2. Res id level deductions like pay later, etc
B29: Discounts Summary | C29: View of the different discounts running on your restaurant during this report period
B30: Glossary | C30: Descriptions of the terms used in the Order Level tab

Sheet Payout Breakup
B2: Payout Breakup
B3: S.No. | C3: Particular | D3: Delivered Orders | E3: Cancelled/ Rejected Orders | F3: Total
C4: Number of Orders | D4: =IFERROR(COUNTIF('Order Level'!I:I,"Delivered"),0) -> 151 | E4: =IFERROR(COUNTIF('Order Level'!I:I,"CANCELLED")+COUNTIF('Order Level'!I:I,"REJECTED")+COUNTIF('Order Level'!I:I,"TIMEDOUT"),0) -> 0 | F4: =SUM(D4:E4) -> 151
B6: A | C6: Net order value ( 1 + 2 + 3 - 4 - 5 + 6 - 7 + 8 ) | D6: =D7+D8+D9-D10-D11+D14+D12-D13 -> 68930.4 | E6: =E7+E8+E9-E10-E11+E12+E14 -> 0 | F6: =F7+F8+F9-F10-F11+F14+F12-F13 -> 68930.4
B7: 1 | C7: ='Order Level'!O1 -> Subtotal (items total) | D7: =SUMIFS('Order Level'!$O:$O,'Order Level'!$I:$I,"DELIVERED") -> 65648 | E7: 0 | F7: =SUM(D7:E7) -> 65648
B8: 2 | C8: ='Order Level'!P1 -> Packaging charge | D8: =IFERROR(SUMIFS('Order Level'!$P:$P,'Order Level'!$I:$I,"DELIVERED"),0) -> 0 | E8: 0 | F8: =SUM(D8:E8) -> 0
B9: 3 | C9: ='Order Level'!Q1 -> Delivery charge for restaurants on self logistics | D9: =IFERROR(SUMIFS('Order Level'!$Q:$Q,'Order Level'!$I:$I,"DELIVERED"),0) -> 0 | E9: 0 | F9: =SUM(D9:E9) -> 0
B10: 4 | C10: ='Order Level'!R1 -> Restaurant discount [Promo] | D10: =IFERROR(SUMIFS('Order Level'!$R:$R,'Order Level'!$I:$I,"DELIVERED"),0) -> 0 | E10: 0 | F10: =SUM(D10:E10) -> 0
B11: 5 | C11: ='Order Level'!S1 -> Restaurant Discount [BOGO, Freebies, Gold, Brand pack & others] | D11: =IFERROR(SUMIFS('Order Level'!$S:$S,'Order Level'!$I:$I,"DELIVERED"),0) -> 0 | E11: 0 | F11: =SUM(D11:E11) -> 0
B12: 6 | C12: ='Order Level'!T1 -> Brand pack subscription fee | D12: =IFERROR(SUMIFS('Order Level'!$T:$T,'Order Level'!$I:$I,"DELIVERED"),0) -> 0 | E12: 0 | F12: =SUM(D12:E12) -> 0
B13: 7 | C13: ='Order Level'!U1 -> Delivery charge discount / Relisting discount | D13: =IFERROR(SUMIFS('Order Level'!$U:$U,'Order Level'!$I:$I,"DELIVERED"),0) -> 0 | E13: 0 | F13: =SUM(D13:E13) -> 0
B14: 8 | C14: ='Order Level'!V1 -> Total GST collected from customers | D14: =IFERROR(SUMIFS('Order Level'!$V:$V,'Order Level'!$I:$I,"DELIVERED"),0) -> 3282.4 | E14: =IFERROR(SUMIFS('Order Level'!$V:$V,'Order Level'!$I:$I,"CANCELLED")+SUMIFS('Order Level'!$V:$V,'Order Level'!$I:$I,"REJECTED")+SUMIFS('Order Level'!$V:$V,'Order Level'!$I:$I,"TIMEDOUT"),0) -> 0 | F14: =SUM(D14:E14) -> 3282.4
B16: 9 | C16: Commissionable value (excludes customer GST) [(A) - (8) + (7) - (6) - (3)] | D16: =D6-D14-D9-D12+D13 -> 65648 | E16: =E6-E14-E9-E12+E13 -> 0 | F16: =F6-F14-F9-F12+F13 -> 65648
B18: B | C18: Service fees & payment mechanism fees ( 10 + 11 ) | D18: =D19+D20 -> 15710.8 | E18: =E19+E20 -> 0 | F18: =F19+F20 -> 15710.8
B19: 10 | C19: =LEFT('Order Level'!Z1,FIND("[",'Order Level'!Z1)-2) -> Service fee | D19: =IFERROR(SUMIFS('Order Level'!$Z:$Z,'Order Level'!$I:$I,"DELIVERED"),0) -> 14442.56 | E19: =IFERROR(SUMIFS('Order Level'!$Z:$Z,'Order Level'!$I:$I,"CANCELLED")+SUMIFS('Order Level'!$Z:$Z,'Order Level'!$I:$I,"REJECTED")+SUMIFS('Order Level'!$Z:$Z,'Order Level'!$I:$I,"TIMEDOUT"),0) -> 0 | F19: =SUM(D19:E19) -> 14442.56
B20: 11 | C20: ='Order Level'!AA1 -> Payment mechanism fee | D20: =IFERROR(SUMIFS('Order Level'!$AA:$AA,'Order Level'!$I:$I,"DELIVERED"),0) -> 1268.24 | E20: =IFERROR(SUMIFS('Order Level'!$AA:$AA,'Order Level'!$I:$I,"CANCELLED")+SUMIFS('Order Level'!$AA:$AA,'Order Level'!$I:$I,"REJECTED")++SUMIFS('Order Level'!$AA:$AA,'Order Level'!$I:$I,"TIMEDOUT"),0) -> 0 | F20: =SUM(D20:E20) -> 1268.24
B22: C | C22: Government charges ( 12 + 13 + 14 + 15 ) | D22: =SUM(D23:D26) -> 6176.09 | E22: =SUM(E23:E26) -> 0 | F22: =SUM(F23:F26) -> 6176.09
B23: 12 | C23: =LEFT('Order Level'!AC1,FIND("(",'Order Level'!AC1)-2) -> Taxes on service & payment mechanism fees | D23: =IFERROR(SUMIFS('Order Level'!$AC:$AC,'Order Level'!$I:$I,"DELIVERED"),0) -> 2828.04 | E23: =SUMIFS('Order Level'!$AC:$AC,'Order Level'!$I:$I,"CANCELLED")+SUMIFS('Order Level'!$AC:$AC,'Order Level'!$I:$I,"REJECTED")+SUMIFS('Order Level'!$AC:$AC,'Order Level'!$I:$I,"TIMEDOUT") -> 0 | F23: =SUM(D23:E23) -> 2828.04
B24: 13 | C24: ='Order Level'!AF1&" + "&'Order Level'!AG1 -> Tax collected at source + TCS IGST amount | D24: =IFERROR(SUMIFS('Order Level'!$AF:$AF,'Order Level'!$I:$I,"DELIVERED")+SUMIFS('Order Level'!$AG:$AG,'Order Level'!$I:$I,"DELIVERED"),0) -> 0 | E24: =SUMIFS('Order Level'!$AF:$AF,'Order Level'!$I:$I,"CANCELLED")+SUMIFS('Order Level'!$AG:$AG,'Order Level'!$I:$I,"CANCELLED")+SUMIFS('Order Level'!$AF:$AF,'Order Level'!$I:$I,"REJECTED")+SUMIFS('Order Level'!$AG:$AG,'Order Level'!$I:$I,"REJECTED")+SUMIFS('Order Level'!$AF:$AF,'Order Level'!$I:$I,"TIMEDOUT")+SUMIFS('Order Level'!$AG:$AG,'Order Level'!$I:$I,"TIMEDOUT") -> 0 | F24: =SUM(D24:E24) -> 0
B25: 14 | C25: ='Order Level'!AH1 -> TDS 194O amount | D25: =IFERROR(SUMIFS('Order Level'!$AH:$AH,'Order Level'!$I:$I,"DELIVERED"),0) -> 65.65 | E25: =IFERROR(SUMIFS('Order Level'!$AH:$AH,'Order Level'!$I:$I,"CANCELLED")+SUMIFS('Order Level'!$AH:$AH,'Order Level'!$I:$I,"REJECTED")+SUMIFS('Order Level'!$AH:$AH,'Order Level'!$I:$I,"TIMEDOUT"),0) -> 0 | F25: =SUM(D25:E25) -> 65.65
B26: 15 | C26: ='Order Level'!AI1 -> GST paid by Zomato on behalf of restaurant - under section 9(5) | D26: =IFERROR(SUMIFS('Order Level'!$AI:$AI,'Order Level'!$I:$I,"DELIVERED"),0) -> 3282.4 | E26: 0 | F26: =SUM(D26:E26) -> 3282.4
B28: D | C28: Other order level deductions ( 16 + 17 + 18 ) | D28: =D29+SUM(D38:D39) -> 0 | E28: =E29+SUM(E38:E39) -> 0 | F28: =F29+SUM(F38:F39) -> 0
B29: 16 | C29: Other Order level deductions | D29: =SUM(D30:D37) -> 0 | E29: =SUM(E30:E37) -> 0 | F29: =SUM(D29:E29) -> 0
C30: ='Order Level'!AL1 -> Customer Compensation/Recoupment | D30: =IFERROR(SUMIFS('Order Level'!$AL:$AL,'Order Level'!$I:$I,"DELIVERED"),0) -> 0 | E30: =IFERROR(SUMIFS('Order Level'!$AL:$AL,'Order Level'!$I:$I,"CANCELLED"),0) -> 0 | F30: =SUM(D30:E30) -> 0
C31: Rejection Penalty | D31: 0 | E31: =IFERROR(SUMIFS('Order Level'!$AL:$AL,'Order Level'!$I:$I,"REJECTED")+SUMIFS('Order Level'!$AL:$AL,'Order Level'!$I:$I,"TIMEDOUT"),0) -> 0 | F31: =SUM(D31:E31) -> 0
C32: ='Order Level'!AM1 -> Delivery Charges Recovery | D32: =IFERROR(SUMIFS('Order Level'!$AM:$AM,'Order Level'!$I:$I,"DELIVERED"),0) -> 0 | E32: =IFERROR(SUMIFS('Order Level'!$AM:$AM,'Order Level'!$I:$I,"CANCELLED")+SUMIFS('Order Level'!$AM:$AM,'Order Level'!$I:$I,"REJECTED")+SUMIFS('Order Level'!$AM:$AM,'Order Level'!$I:$I,"TIMEDOUT"),0) -> 0 | F32: =SUM(D32:E32) -> 0
C33: ='Order Level'!AO1 -> Credit note/(Debit Note) adjustment | D33: =IFERROR(SUMIFS('Order Level'!$AO:$AO,'Order Level'!$I:$I,"DELIVERED"),0) -> 0 | E33: =IFERROR(SUMIFS('Order Level'!$AO:$AO,'Order Level'!$I:$I,"CANCELLED")+SUMIFS('Order Level'!$AO:$AO,'Order Level'!$I:$I,"REJECTED")+SUMIFS('Order Level'!$AO:$AO,'Order Level'!$I:$I,"TIMEDOUT"),0) -> 0 | F33: =SUM(D33:E33) -> 0
C34: ='Order Level'!AP1 -> Promo recovery adjustment | D34: =IFERROR(SUMIFS('Order Level'!$AP:$AP,'Order Level'!$I:$I,"DELIVERED"),0) -> 0 | E34: =IFERROR(SUMIFS('Order Level'!$AP:$AP,'Order Level'!$I:$I,"CANCELLED")+SUMIFS('Order Level'!$AP:$AP,'Order Level'!$I:$I,"REJECTED")+SUMIFS('Order Level'!$AP:$AP,'Order Level'!$I:$I,"TIMEDOUT"),0) -> 0 | F34: =SUM(D34:E34) -> 0
C35: ='Order Level'!AQ1 -> Extra Inventory Ads and Misc. (order level deduction) | D35: =IFERROR(SUMIFS('Order Level'!$AQ:$AQ,'Order Level'!$I:$I,"DELIVERED"),0) -> 0 | E35: =IFERROR(SUMIFS('Order Level'!$AQ:$AQ,'Order Level'!$I:$I,"CANCELLED")+SUMIFS('Order Level'!$AQ:$AQ,'Order Level'!$I:$I,"REJECTED")+SUMIFS('Order Level'!$AQ:$AQ,'Order Level'!$I:$I,"TIMEDOUT"),0) -> 0 | F35: =SUM(D35:E35) -> 0
C36: Brand loyalty points redemption | D36: =IFERROR(SUMIFS('Order Level'!$AR:$AR,'Order Level'!$I:$I,"DELIVERED"),0) -> 0 | E36: =IFERROR(SUMIFS('Order Level'!$AR:$AR,'Order Level'!$I:$I,"CANCELLED")+SUMIFS('Order Level'!$AR:$AR,'Order Level'!$I:$I,"REJECTED")+SUMIFS('Order Level'!$AR:$AR,'Order Level'!$I:$I,"TIMEDOUT"),0) -> 0 | F36: =SUM(D36:E36) -> 0
C37: Express Order Fee | D37: =IFERROR(SUMIFS('Order Level'!$AS:$AS,'Order Level'!$I:$I,"DELIVERED"),0) -> 0 | E37: =IFERROR(SUMIFS('Order Level'!$AS:$AS,'Order Level'!$I:$I,"CANCELLED")+SUMIFS('Order Level'!$AS:$AS,'Order Level'!$I:$I,"REJECTED")+SUMIFS('Order Level'!$AS:$AS,'Order Level'!$I:$I,"TIMEDOUT"),0) -> 0 | F37: =SUM(D37:E37) -> 0
B38: 17 | C38: ='Order Level'!AN1 -> Amount received in cash (on self delivery orders) | D38: =IFERROR(SUMIFS('Order Level'!$AN:$AN,'Order Level'!$I:$I,"DELIVERED"),0) -> 0 | E38: =IFERROR(SUMIFS('Order Level'!$AN:$AN,'Order Level'!$I:$I,"CANCELLED")+SUMIFS('Order Level'!$AN:$AN,'Order Level'!$I:$I,"REJECTED")+SUMIFS('Order Level'!$AN:$AN,'Order Level'!$I:$I,"TIMEDOUT"),0) -> 0 | F38: =SUM(D38:E38) -> 0
B39: 18 | C39: Adjustments from previous weeks (Refer to Annexure : "Addition/ Deduction Details") | D39: =IFERROR(SUMIFS('Addition Deductions Details'!G:G,'Addition Deductions Details'!B:B,"Total adjustments from previous weeks"),0) -> 0 | E39: - | F39: =SUM(D39:E39) -> 0
B41: E | C41: Investment in growth services ( 19 + 20 + 21 ) | D41: =SUM(D42:D44) -> 0 | E41: - | F41: =SUM(F42:F44) -> 0
B42: 19 | C42: Total Ads (inc. 18% GST) (Refer to Annexure : "Addition/ Deduction Details") | D42: {=IFERROR( SUMPRODUCT( (--(INDEX('Addition Deductions Details'!B:B, MATCH("Deduction Type", 'Addition Deductions Details'!B:B, 0)): INDEX('Addition Deductions Details'!B:B, MATCH("Total Ads & miscellaneous services", 'Addition Deductions Details'!B:B, 0)) ="ADS")), INDEX('Addition Deductions Details'!G:G, MATCH("Deduction Type", 'Addition Deductions Details'!B:B, 0)): INDEX('Addition Deductions Details'!G:G, MATCH("Total Ads & miscellaneous services", 'Addition Deductions Details'!B:B, 0)) ) - SUMPRODUCT( (--(INDEX('Addition Deductions Details'!B:B, MATCH("Addition Type", 'Addition Deductions Details'!B:B, 0)): INDEX('Addition Deductions Details'!B:B, MATCH("Total Additions", 'Addition Deductions Details'!B:B, 0)) ="ADS")), INDEX('Addition Deductions Details'!G:G, MATCH("Addition Type", 'Addition Deductions Details'!B:B, 0)): INDEX('Addition Deductions Details'!G:G, MATCH("Total Additions", 'Addition Deductions Details'!B:B, 0)) ), 0)} -> 0 | E42: - | F42: =SUM(D42:E42) -> 0
B43: 20 | C43: Total Dining Ads (inc. 18% GST) | D43: {=IFERROR( SUMPRODUCT( (--(INDEX('Addition Deductions Details'!B:B, MATCH("Deduction Type", 'Addition Deductions Details'!B:B, 0)): INDEX('Addition Deductions Details'!B:B, MATCH("Total Ads & miscellaneous services", 'Addition Deductions Details'!B:B, 0)) ="Dining ADS")), INDEX('Addition Deductions Details'!G:G, MATCH("Deduction Type", 'Addition Deductions Details'!B:B, 0)): INDEX('Addition Deductions Details'!G:G, MATCH("Total Ads & miscellaneous services", 'Addition Deductions Details'!B:B, 0)) ) - SUMPRODUCT( (--(INDEX('Addition Deductions Details'!B:B, MATCH("Addition Type", 'Addition Deductions Details'!B:B, 0)): INDEX('Addition Deductions Details'!B:B, MATCH("Total Additions", 'Addition Deductions Details'!B:B, 0)) ="Dining ADS")), INDEX('Addition Deductions Details'!G:G, MATCH("Addition Type", 'Addition Deductions Details'!B:B, 0)): INDEX('Addition Deductions Details'!G:G, MATCH("Total Additions", 'Addition Deductions Details'!B:B, 0)) ), 0)} -> 0 | E43: - | F43: =SUM(D43:E43) -> 0
B44: 21 | C44: Miscellaneous sevices (Refer to Annexure : "Addition/ Deduction Details") | D44: {=IFERROR( SUMPRODUCT( (--(INDEX('Addition Deductions Details'!B:B, MATCH("Deduction Type", 'Addition Deductions Details'!B:B, 0)+1): INDEX('Addition Deductions Details'!B:B, MATCH("Total Ads & miscellaneous services", 'Addition Deductions Details'!B:B, 0)-1) <> "ADS")), (--(INDEX('Addition Deductions Details'!B:B, MATCH("Deduction Type", 'Addition Deductions Details'!B:B, 0)+1): INDEX('Addition Deductions Details'!B:B, MATCH("Total Ads & miscellaneous services", 'Addition Deductions Details'!B:B, 0)-1) <> "Dining ADS")), INDEX('Addition Deductions Details'!G:G, MATCH("Deduction Type", 'Addition Deductions Details'!B:B, 0)+1): INDEX('Addition Deductions Details'!G:G, MATCH("Total Ads & miscellaneous services", 'Addition Deductions Details'!B:B, 0)-1) ) - SUMPRODUCT( (--(INDEX('Addition Deductions Details'!B:B, MATCH("Addition Type", 'Addition Deductions Details'!B:B, 0)+1): INDEX('Addition Deductions Details'!B:B, MATCH("Total Additions", 'Addition Deductions Details'!B:B, 0)-1) <> "ADS")), (--(INDEX('Addition Deductions Details'!B:B, MATCH("Addition Type", 'Addition Deductions Details'!B:B, 0)+1): INDEX('Addition Deductions Details'!B:B, MATCH("Total Additions", 'Addition Deductions Details'!B:B, 0)-1) <> "Dining ADS")), INDEX('Addition Deductions Details'!G:G, MATCH("Addition Type", 'Addition Deductions Details'!B:B, 0)+1): INDEX('Addition Deductions Details'!G:G, MATCH("Total Additions", 'Addition Deductions Details'!B:B, 0)-1) ), 0)} -> 0 | E44: - | F44: =SUM(D44:E44) -> 0
B46: F | C46: Investment in Hyperpure | D46: =IFERROR(SUMIFS('Addition Deductions Details'!G:G,'Addition Deductions Details'!B:B,"Total Hyperpure"),0) -> 0 | E46: - | F46: =SUM(D46:E46) -> 0
B48: G | C48: Other Deductions | D48: =IFERROR(SUMIFS('Addition Deductions Details'!G:G,'Addition Deductions Details'!B:B,"Total deductions"),0) -> 0 | E48: - | F48: =SUM(D48:E48) -> 0
B50: H | C50: Total Additions ( 24 + 25 + 26 + 27 ) | D50: =SUM(D51:D54) -> 0 | E50: =SUM(E51:E54) -> 0 | F50: =SUM(F51:F54) -> 0
...

Sheet Order Level
A1: S.No. | B1: Order ID | C1: Order Date | D1: Week No. | E1: Res. name | F1: Res. ID | G1: Discount Construct | H1: Mode of payment | I1: Order status (Delivered/ Cancelled/ Rejected) | J1: Cancellation policy (% Amount refunded back to restaurant partner) | K1: Cancellation/ Rejection Reason | L1: Cancelled/ Rejected State (Order status at the time it was cancelled/ rejected) | M1: Order type | N1: Delivery State code | O1: Subtotal (items total) | P1: Packaging charge | Q1: Delivery charge for restaurants on self logistics | R1: Restaurant discount [Promo] | S1: Restaurant Discount [BOGO, Freebies, Gold, Brand pack & others] | T1: Brand pack subscription fee | U1: Delivery charge discount / Relisting discount | V1: Total GST collected from customers | W1: Net order value [(1) + (2) + (3) - (4) - (5) + (6) - (7) + (8)] | X1: Commissionable value (excludes customer GST) [(A) + (7) - (8) - (6) - (3)] | Y1: Service fees % | Z1: Service fee [ (9) * (10) ] | AA1: Payment mechanism fee | AB1: Service fee & payment mechanism fees [(11) + (12)] | AC1: Taxes on service & payment mechanism fees (B) * 18% | AD1: Applicable amount for TCS | AE1: Applicable amount for 9(5) | AF1: Tax collected at source | AG1: TCS IGST amount | AH1: TDS 194O amount | AI1: GST paid by Zomato on behalf of restaurant - under section 9(5) | AJ1: GST to be paid by Restaurant partner to Govt. | AK1: Government charges [(13) + (16) + (17) + (18) + (19)] | AL1: Customer Compensation/Recoupment | AM1: Delivery Charges Recovery | AN1: Amount received in cash (on self delivery orders) | AO1: Credit note/(Debit Note) adjustment | AP1: Promo recovery adjustment | AQ1: Extra Inventory Ads and Misc. (order level deduction) | AR1: Brand loyalty points redemption | AS1: Express Order Fee | AT1: Other order-level deductions [(21) + (22) + (23) + (24) + (25) + (26) + (27) + (28)] | AU1: Net Deductions (B) + (C) + (D) | AV1: Net Additions (cancellation refund for cancelled orders/Tip for Kitchen Staff for delivered orders) | AW1: Order level Payout (A) - (E) + (F) | AX1: Settlement status | AY1: Settlement date | AZ1: Bank UTR | BA1: Unsettled Amount | BB1: Customer ID
A2: #REF! | B2: #REF! | C2: #REF!
A3: 1 | B3: 7746177218 | C3: 2026-02-01 10:08:07 | D3: 5 | E3: Purnabramha Aurangabad | F3: 20523448 | G3: NA | H3: ONLINE | I3: DELIVERED | J3: NA | K3: NA | L3: NA | M3: O2 | N3: 27 | O3: 392 | P3: 0 | Q3: 0 | R3: 0 | S3: 0 | T3: 0 | U3: 0 | V3: 19.6 | W3: 411.6 | X3: 392 | Y3: 22 | Z3: 86.24 | AA3: 7.57 | AB3: 93.81 | AC3: 16.88 | AD3: 0 | AE3: 392 | AF3: 0 | AG3: 0 | AH3: 0.39 | AI3: 19.6 | AJ3: 0 | AK3: 36.87 | AL3: 0 | AM3: 0 | AN3: 0 | AO3: 0 | AP3: 0 | AQ3: 0 | AR3: 0 | AS3: 0 | AT3: 0 | AU3: 130.68 | AV3: 0 | AW3: 280.92 | AX3: settled | AY3: 2026-02-04 05:30:00 | AZ3: CITIN26617354846 | BA3: 0 | BB3: 2e2998d6af2106e0dcb612346439c26ca9640aece1042d94b0b7f8461bed0954
A4: 2 | B4: 7746964905 | C4: 2026-02-01 12:23:49 | D4: 5 | E4: Purnabramha Aurangabad | F4: 20523448 | G4: NA | H4: ONLINE | I4: DELIVERED | J4: NA | K4: NA | L4: NA | M4: O2 | N4: 27 | O4: 882 | P4: 0 | Q4: 0 | R4: 0 | S4: 0 | T4: 0 | U4: 0 | V4: 44.1 | W4: 926.1 | X4: 882 | Y4: 22 | Z4: 194.04 | AA4: 17.04 | AB4: 211.08 | AC4: 38 | AD4: 0 | AE4: 882 | AF4: 0 | AG4: 0 | AH4: 0.88 | AI4: 44.1 | AJ4: 0 | AK4: 82.98 | AL4: 0 | AM4: 0 | AN4: 0 | AO4: 0 | AP4: 0 | AQ4: 0 | AR4: 0 | AS4: 0 | AT4: 0 | AU4: 294.06 | AV4: 0 | AW4: 632.04 | AX4: settled | AY4: 2026-02-04 05:30:00 | AZ4: CITIN26617354846 | BA4: 0 | BB4: 7f23054f6f960a1cacac0abeb268976b02fe221a3c2b22f2af0894e4814fefb8
A5: 3 | B5: 7750721789 | C5: 2026-02-01 13:50:04 | D5: 5 | E5: Purnabramha Aurangabad | F5: 20523448 | G5: NA | H5: ONLINE | I5: DELIVERED | J5: NA | K5: NA | L5: NA | M5: O2 | N5: 27 | O5: 435 | P5: 0 | Q5: 0 | R5: 0 | S5: 0 | T5: 0 | U5: 0 | V5: 21.75 | W5: 456.75 | X5: 435 | Y5: 22 | Z5: 95.7 | AA5: 8.4 | AB5: 104.1 | AC5: 18.74 | AD5: 0 | AE5: 435 | AF5: 0 | AG5: 0 | AH5: 0.44 | AI5: 21.75 | AJ5: 0 | AK5: 40.93 | AL5: 0 | AM5: 0 | AN5: 0 | AO5: 0 | AP5: 0 | AQ5: 0 | AR5: 0 | AS5: 0 | AT5: 0 | AU5: 145.03 | AV5: 0 | AW5: 311.72 | AX5: settled | AY5: 2026-02-04 05:30:00 | AZ5: CITIN26617354846 | BA5: 0 | BB5: 7cef5ae91ff6ff5a607f6c6791c4f60e2d9c1a376881ae284486640e196d54fc
A6: 4 | B6: 7749406453 | C6: 2026-02-01 14:49:12 | D6: 5 | E6: Purnabramha Aurangabad | F6: 20523448 | G6: NA | H6: ONLINE | I6: DELIVERED | J6: NA | K6: NA | L6: NA | M6: O2 | N6: 27 | O6: 355 | P6: 0 | Q6: 0 | R6: 0 | S6: 0 | T6: 0 | U6: 0 | V6: 17.75 | W6: 372.75 | X6: 355 | Y6: 22 | Z6: 78.1 | AA6: 6.86 | AB6: 84.96 | AC6: 15.29 | AD6: 0 | AE6: 355 | AF6: 0 | AG6: 0 | AH6: 0.36 | AI6: 17.75 | AJ6: 0 | AK6: 33.4 | AL6: 0 | AM6: 0 | AN6: 0 | AO6: 0 | AP6: 0 | AQ6: 0 | AR6: 0 | AS6: 0 | AT6: 0 | AU6: 118.36 | AV6: 0 | AW6: 254.39 | AX6: settled | AY6: 2026-02-04 05:30:00 | AZ6: CITIN26617354846 | BA6: 0 | BB6: efba94c471f35f44cdd7d4d75c2336bc09c55f33b035e010451dae036eea5d7a
A7: 5 | B7: 7751883149 | C7: 2026-02-01 15:23:00 | D7: 5 | E7: Purnabramha Aurangabad | F7: 20523448 | G7: NA | H7: ONLINE | I7: DELIVERED | J7: NA | K7: NA | L7: NA | M7: O2 | N7: 27 | O7: 588 | P7: 0 | Q7: 0 | R7: 0 | S7: 0 | T7: 0 | U7: 0 | V7: 29.4 | W7: 617.4 | X7: 588 | Y7: 22 | Z7: 129.36 | AA7: 11.36 | AB7: 140.72 | AC7: 25.32 | AD7: 0 | AE7: 588 | AF7: 0 | AG7: 0 | AH7: 0.59 | AI7: 29.4 | AJ7: 0 | AK7: 55.31 | AL7: 0 | AM7: 0 | AN7: 0 | AO7: 0 | AP7: 0 | AQ7: 0 | AR7: 0 | AS7: 0 | AT7: 0 | AU7: 196.03 | AV7: 0 | AW7: 421.37 | AX7: settled | AY7: 2026-02-04 05:30:00 | AZ7: CITIN26617354846 | BA7: 0 | BB7: 87abba2bcbbdf63e814da6ffd7e3acd2936063b0323f12df83cac894193feb93
A8: 6 | B8: 7745811138 | C8: 2026-02-01 19:01:52 | D8: 5 | E8: Purnabramha Aurangabad | F8: 20523448 | G8: NA | H8: ONLINE | I8: DELIVERED | J8: NA | K8: NA | L8: NA | M8: O2 | N8: 27 | O8: 375 | P8: 0 | Q8: 0 | R8: 0 | S8: 0 | T8: 0 | U8: 0 | V8: 18.75 | W8: 393.75 | X8: 375 | Y8: 22 | Z8: 82.5 | AA8: 7.24 | AB8: 89.74 | AC8: 16.15 | AD8: 0 | AE8: 375 | AF8: 0 | AG8: 0 | AH8: 0.38 | AI8: 18.75 | AJ8: 0 | AK8: 35.28 | AL8: 0 | AM8: 0 | AN8: 0 | AO8: 0 | AP8: 0 | AQ8: 0 | AR8: 0 | AS8: 0 | AT8: 0 | AU8: 125.02 | AV8: 0 | AW8: 268.73 | AX8: settled | AY8: 2026-02-04 05:30:00 | AZ8: CITIN26617354846 | BA8: 0 | BB8: 5ecbf54f2e9ee971303406209cc18bfc23fb2c12425f0de7f566f4853b81cbe3
A9: 7 | B9: 7750785073 | C9: 2026-02-01 19:58:41 | D9: 5 | E9: Purnabramha Aurangabad | F9: 20523448 | G9: NA | H9: ONLINE | I9: DELIVERED | J9: NA | K9: NA | L9: NA | M9: O2 | N9: 27 | O9: 153 | P9: 0 | Q9: 0 | R9: 0 | S9: 0 | T9: 0 | U9: 0 | V9: 7.65 | W9: 160.65 | X9: 153 | Y9: 22 | Z9: 33.66 | AA9: 2.96 | AB9: 36.62 | AC9: 6.59 | AD9: 0 | AE9: 153 | AF9: 0 | AG9: 0 | AH9: 0.15 | AI9: 7.65 | AJ9: 0 | AK9: 14.39 | AL9: 0 | AM9: 0 | AN9: 0 | AO9: 0 | AP9: 0 | AQ9: 0 | AR9: 0 | AS9: 0 | AT9: 0 | AU9: 51.01 | AV9: 0 | AW9: 109.64 | AX9: settled | AY9: 2026-02-04 05:30:00 | AZ9: CITIN26617354846 | BA9: 0 | BB9: 1ccac4a0179fccad94ee71572e0ca5386af085cd6d181fde1276e99ed3078bb7
A10: 8 | B10: 7748138786 | C10: 2026-02-02 11:31:31 | D10: 6 | E10: Purnabramha Aurangabad | F10: 20523448 | G10: NA | H10: ONLINE | I10: DELIVERED | J10: NA | K10: NA | L10: NA | M10: O2 | N10: 27 | O10: 513 | P10: 0 | Q10: 0 | R10: 0 | S10: 0 | T10: 0 | U10: 0 | V10: 25.65 | W10: 538.65 | X10: 513 | Y10: 22 | Z10: 112.86 | AA10: 9.91 | AB10: 122.77 | AC10: 22.09 | AD10: 0 | AE10: 513 | AF10: 0 | AG10: 0 | AH10: 0.51 | AI10: 25.65 | AJ10: 0 | AK10: 48.25 | AL10: 0 | AM10: 0 | AN10: 0 | AO10: 0 | AP10: 0 | AQ10: 0 | AR10: 0 | AS10: 0 | AT10: 0 | AU10: 171.02 | AV10: 0 | AW10: 367.63 | AX10: settled | AY10: 2026-02-11 05:30:00 | AZ10: CITIN26620176758 | BA10: 0 | BB10: faf402b0c7a4a49e9c2d19eb9d839996329a1410872cb2746b69992b7014faab
A11: 9 | B11: 7749474492 | C11: 2026-02-02 19:07:56 | D11: 6 | E11: Purnabramha Aurangabad | F11: 20523448 | G11: NA | H11: ONLINE | I11: DELIVERED | J11: NA | K11: NA | L11: NA | M11: O2 | N11: 27 | O11: 436 | P11: 0 | Q11: 0 | R11: 0 | S11: 0 | T11: 0 | U11: 0 | V11: 21.8 | W11: 457.8 | X11: 436 | Y11: 22 | Z11: 95.92 | AA11: 8.42 | AB11: 104.34 | AC11: 18.79 | AD11: 0 | AE11: 436 | AF11: 0 | AG11: 0 | AH11: 0.44 | AI11: 21.8 | AJ11: 0 | AK11: 41.03 | AL11: 0 | AM11: 0 | AN11: 0 | AO11: 0 | AP11: 0 | AQ11: 0 | AR11: 0 | AS11: 0 | AT11: 0 | AU11: 145.37 | AV11: 0 | AW11: 312.43 | AX11: settled | AY11: 2026-02-11 05:30:00 | AZ11: CITIN26620176758 | BA11: 0 | BB11: 7f23054f6f960a1cacac0abeb268976b02fe221a3c2b22f2af0894e4814fefb8
A12: 10 | B12: 7753158349 | C12: 2026-02-02 19:39:55 | D12: 6 | E12: Purnabramha Aurangabad | F12: 20523448 | G12: NA | H12: ONLINE | I12: DELIVERED | J12: NA | K12: NA | L12: NA | M12: O2 | N12: 27 | O12: 419 | P12: 0 | Q12: 0 | R12: 0 | S12: 0 | T12: 0 | U12: 0 | V12: 20.95 | W12: 439.95 | X12: 419 | Y12: 22 | Z12: 92.18 | AA12: 8.1 | AB12: 100.28 | AC12: 18.05 | AD12: 0 | AE12: 419 | AF12: 0 | AG12: 0 | AH12: 0.42 | AI12: 20.95 | AJ12: 0 | AK12: 39.42 | AL12: 0 | AM12: 0 | AN12: 0 | AO12: 0 | AP12: 0 | AQ12: 0 | AR12: 0 | AS12: 0 | AT12: 0 | AU12: 139.7 | AV12: 0 | AW12: 300.25 | AX12: settled | AY12: 2026-02-11 05:30:00 | AZ12: CITIN26620176758 | BA12: 0 | BB12: 8d0d9cb9c9ae68dc70da1549bb32f27488cd45522bb084c83af1c0e10268640a
A13: 11 | B13: 7756381152 | C13: 2026-02-02 19:44:56 | D13: 6 | E13: Purnabramha Aurangabad | F13: 20523448 | G13: NA | H13: ONLINE | I13: DELIVERED | J13: NA | K13: NA | L13: NA | M13: O2 | N13: 27 | O13: 509 | P13: 0 | Q13: 0 | R13: 0 | S13: 0 | T13: 0 | U13: 0 | V13: 25.45 | W13: 534.45 | X13: 509 | Y13: 22 | Z13: 111.98 | AA13: 9.83 | AB13: 121.81 | AC13: 21.93 | AD13: 0 | AE13: 509 | AF13: 0 | AG13: 0 | AH13: 0.51 | AI13: 25.45 | AJ13: 0 | AK13: 47.89 | AL13: 0 | AM13: 0 | AN13: 0 | AO13: 0 | AP13: 0 | AQ13: 0 | AR13: 0 | AS13: 0 | AT13: 0 | AU13: 169.7 | AV13: 0 | AW13: 364.75 | AX13: settled | AY13: 2026-02-11 05:30:00 | AZ13: CITIN26620176758 | BA13: 0 | BB13: 036a32b4f0c0ed1110d5ed7a707db418fb8ca62a5fb5111ed22ee69ecd3cbd8f
A14: 12 | B14: 7756402099 | C14: 2026-02-03 11:56:28 | D14: 6 | E14: Purnabramha Aurangabad | F14: 20523448 | G14: NA | H14: ONLINE | I14: DELIVERED | J14: NA | K14: NA | L14: NA | M14: O2 | N14: 27 | O14: 229 | P14: 0 | Q14: 0 | R14: 0 | S14: 0 | T14: 0 | U14: 0 | V14: 11.45 | W14: 240.45 | X14: 229 | Y14: 22 | Z14: 50.38 | AA14: 4.42 | AB14: 54.8 | AC14: 9.87 | AD14: 0 | AE14: 229 | AF14: 0 | AG14: 0 | AH14: 0.23 | AI14: 11.45 | AJ14: 0 | AK14: 21.55 | AL14: 0 | AM14: 0 | AN14: 0 | AO14: 0 | AP14: 0 | AQ14: 0 | AR14: 0 | AS14: 0 | AT14: 0 | AU14: 76.35 | AV14: 0 | AW14: 164.1 | AX14: settled | AY14: 2026-02-11 05:30:00 | AZ14: CITIN26620176758 | BA14: 0 | BB14: 68beb0d34d36a356fd4c9da9131a59f5d7bb88698367f380da2c1fab070ea262
... A153: 151 | B153: 7843668230 | C153: 2026-02-28 20:58:53 | D153: 9 | E153: Purnabramha Aurangabad | F153: 20523448 | G153: NA | H153: ONLINE | I153: DELIVERED | J153: NA | K153: NA | L153: NA | M153: O2 | N153: 27 | O153: 425 | P153: 0 | Q153: 0 | R153: 0 | S153: 0 | T153: 0 | U153: 0 | V153: 21.25 | W153: 446.25 | X153: 425 | Y153: 22 | Z153: 93.5 | AA153: 8.21 | AB153: 101.71 | AC153: 18.31 | AD153: 0 | AE153: 425 | AF153: 0 | AG153: 0 | AH153: 0.42 | AI153: 21.25 | AJ153: 0 | AK153: 39.98 | AL153: 0 | AM153: 0 | AN153: 0 | AO153: 0 | AP153: 0 | AQ153: 0 | AR153: 0 | AS153: 0 | AT153: 0 | AU153: 141.69 | AV153: 0 | AW153: 304.56 | AX153: pending | AY153: NA | AZ153: NA | BA153: 304.56 | BB153: d821481290e776357e257375cf3182c948f84e7902d3302d79f4639d6e7e41e8

Sheet Addition Deductions Details
B1: Addition/ Deduction Details (non-order level additions & deductions and adjustments from previous weeks)
B2: =Summary!C28 -> Summarized view on : 1. Res id level additions like 194 H, etc 2. Res id level deductions like pay later, etc
B5: Addition Type
B6: Type | C6: NA | D6: Invoice No/Order id | E6: Order date | F6: Settlement status | G6: Total amount | H6: Adjusted amount | I6: Outstanding amount
B7: Total Additions | G7: 0 | H7: 0 | I7: 0
B10: Deduction Type
B11: A) Investments in growth services
B12: Type | C12: Res id for which deduction created | D12: Invoice No/Campaign id | E12: Deduction time period | F12: Settlement Status | G12: Total amount | H12: Adjusted amount | I12: Outstanding amount
B13: Total Ads & miscellaneous services | G13: 0 | H13: 0 | I13: 0
B15: B) Investments in Hyperpure
B16: Type | C16: Res id for which deduction created | D16: OrderId | E16: Deduction time period | F16: Settlement Status | G16: Total amount | H16: Adjusted amount | I16: Outstanding amount
B17: Total Hyperpure | G17: 0 | H17: 0 | I17: 0
B19: C) Other deductions
B20: D) Adjustments from previous weeks
B21: Total Deductions (A) + (B) + (C) | G21: 0 | H21: 0 | I21: 0

Sheet Discounts Summary
C1: Offers and Discounts Summary
C2: =Summary!C29 -> View of the different discounts running on your restaurant during this report period
C4: Discount Construct | D4: Orders | E4: ='Order Level'!O1 -> Subtotal (items total) | F4: Discount given | G4: Discount given per order | H4: Effective Discount %
C5: {=_xludf.UNIQUE('Order Level'!G3:G1026746)} -> #NAME? | D5: =IF(COUNTIFS('Order Level'!$I:$I,"delivered",'Order Level'!$G:$G,'Discounts Summary'!$C5)=0,"",COUNTIFS('Order Level'!$I:$I,"delivered",'Order Level'!$G:$G,'Discounts Summary'!$C5)) | E5: =IF(SUMIFS('Order Level'!$O:$O,'Order Level'!$I:$I,"Delivered",'Order Level'!$G:$G,'Discounts Summary'!$C5)=0,"",SUMIFS('Order Level'!$O:$O,'Order Level'!$I:$I,"Delivered",'Order Level'!$G:$G,'Discounts Summary'!$C5)) | F5: =IF(SUMIF('Order Level'!$G:$G,$C5,'Order Level'!R:R)=0,"",SUMIF('Order Level'!$G:$G,$C5,'Order Level'!R:R)) | G5: =IFERROR(F5/D5,"") | H5: =IFERROR(F5/E5,"")
D6: =IF(COUNTIFS('Order Level'!$I:$I,"delivered",'Order Level'!$G:$G,'Discounts Summary'!$C6)=0,"",COUNTIFS('Order Level'!$I:$I,"delivered",'Order Level'!$G:$G,'Discounts Summary'!$C6)) | E6: =IF(SUMIFS('Order Level'!$O:$O,'Order Level'!$I:$I,"Delivered",'Order Level'!$G:$G,'Discounts Summary'!$C6)=0,"",SUMIFS('Order Level'!$O:$O,'Order Level'!$I:$I,"Delivered",'Order Level'!$G:$G,'Discounts Summary'!$C6)) | F6: =IF(SUMIF('Order Level'!$G:$G,$C6,'Order Level'!R:R)=0,"",SUMIF('Order Level'!$G:$G,$C6,'Order Level'!R:R)) | G6: =IFERROR(F6/D6,"") | H6: =IFERROR(F6/E6,"")
D7: =IF(COUNTIFS('Order Level'!$I:$I,"delivered",'Order Level'!$G:$G,'Discounts Summary'!$C7)=0,"",COUNTIFS('Order Level'!$I:$I,"delivered",'Order Level'!$G:$G,'Discounts Summary'!$C7)) | E7: =IF(SUMIFS('Order Level'!$O:$O,'Order Level'!$I:$I,"Delivered",'Order Level'!$G:$G,'Discounts Summary'!$C7)=0,"",SUMIFS('Order Level'!$O:$O,'Order Level'!$I:$I,"Delivered",'Order Level'!$G:$G,'Discounts Summary'!$C7)) | F7: =IF(SUMIF('Order Level'!$G:$G,$C7,'Order Level'!R:R)=0,"",SUMIF('Order Level'!$G:$G,$C7,'Order Level'!R:R)) | G7: =IFERROR(F7/D7,"") | H7: =IFERROR(F7/E7,"")
D8: =IF(COUNTIFS('Order Level'!$I:$I,"delivered",'Order Level'!$G:$G,'Discounts Summary'!$C8)=0,"",COUNTIFS('Order Level'!$I:$I,"delivered",'Order Level'!$G:$G,'Discounts Summary'!$C8)) | E8: =IF(SUMIFS('Order Level'!$O:$O,'Order Level'!$I:$I,"Delivered",'Order Level'!$G:$G,'Discounts Summary'!$C8)=0,"",SUMIFS('Order Level'!$O:$O,'Order Level'!$I:$I,"Delivered",'Order Level'!$G:$G,'Discounts Summary'!$C8)) | F8: =IF(SUMIF('Order Level'!$G:$G,$C8,'Order Level'!R:R)=0,"",SUMIF('Order Level'!$G:$G,$C8,'Order Level'!R:R)) | G8: =IFERROR(F8/D8,"") | H8: =IFERROR(F8/E8,"")
D9: =IF(COUNTIFS('Order Level'!$I:$I,"delivered",'Order Level'!$G:$G,'Discounts Summary'!$C9)=0,"",COUNTIFS('Order Level'!$I:$I,"delivered",'Order Level'!$G:$G,'Discounts Summary'!$C9)) | E9: =IF(SUMIFS('Order Level'!$O:$O,'Order Level'!$I:$I,"Delivered",'Order Level'!$G:$G,'Discounts Summary'!$C9)=0,"",SUMIFS('Order Level'!$O:$O,'Order Level'!$I:$I,"Delivered",'Order Level'!$G:$G,'Discounts Summary'!$C9)) | F9: =IF(SUMIF('Order Level'!$G:$G,$C9,'Order Level'!R:R)=0,"",SUMIF('Order Level'!$G:$G,$C9,'Order Level'!R:R)) | G9: =IFERROR(F9/D9,"") | H9: =IFERROR(F9/E9,"")
D10: =IF(COUNTIFS('Order Level'!$I:$I,"delivered",'Order Level'!$G:$G,'Discounts Summary'!$C10)=0,"",COUNTIFS('Order Level'!$I:$I,"delivered",'Order Level'!$G:$G,'Discounts Summary'!$C10)) | E10: =IF(SUMIFS('Order Level'!$O:$O,'Order Level'!$I:$I,"Delivered",'Order Level'!$G:$G,'Discounts Summary'!$C10)=0,"",SUMIFS('Order Level'!$O:$O,'Order Level'!$I:$I,"Delivered",'Order Level'!$G:$G,'Discounts Summary'!$C10)) | F10: =IF(SUMIF('Order Level'!$G:$G,$C10,'Order Level'!R:R)=0,"",SUMIF('Order Level'!$G:$G,$C10,'Order Level'!R:R)) | G10: =IFERROR(F10/D10,"") | H10: =IFERROR(F10/E10,"")
D11: =IF(COUNTIFS('Order Level'!$I:$I,"delivered",'Order Level'!$G:$G,'Discounts Summary'!$C11)=0,"",COUNTIFS('Order Level'!$I:$I,"delivered",'Order Level'!$G:$G,'Discounts Summary'!$C11)) | E11: =IF(SUMIFS('Order Level'!$O:$O,'Order Level'!$I:$I,"Delivered",'Order Level'!$G:$G,'Discounts Summary'!$C11)=0,"",SUMIFS('Order Level'!$O:$O,'Order Level'!$I:$I,"Delivered",'Order Level'!$G:$G,'Discounts Summary'!$C11)) | F11: =IF(SUMIF('Order Level'!$G:$G,$C11,'Order Level'!R:R)=0,"",SUMIF('Order Level'!$G:$G,$C11,'Order Level'!R:R)) | G11: =IFERROR(F11/D11,"") | H11: =IFERROR(F11/E11,"")
D12: =IF(COUNTIFS('Order Level'!$I:$I,"delivered",'Order Level'!$G:$G,'Discounts Summary'!$C12)=0,"",COUNTIFS('Order Level'!$I:$I,"delivered",'Order Level'!$G:$G,'Discounts Summary'!$C12)) | E12: =IF(SUMIFS('Order Level'!$O:$O,'Order Level'!$I:$I,"Delivered",'Order Level'!$G:$G,'Discounts Summary'!$C12)=0,"",SUMIFS('Order Level'!$O:$O,'Order Level'!$I:$I,"Delivered",'Order Level'!$G:$G,'Discounts Summary'!$C12)) | F12: =IF(SUMIF('Order Level'!$G:$G,$C12,'Order Level'!R:R)=0,"",SUMIF('Order Level'!$G:$G,$C12,'Order Level'!R:R)) | G12: =IFERROR(F12/D12,"") | H12: =IFERROR(F12/E12,"")
D13: =IF(COUNTIFS('Order Level'!$I:$I,"delivered",'Order Level'!$G:$G,'Discounts Summary'!$C13)=0,"",COUNTIFS('Order Level'!$I:$I,"delivered",'Order Level'!$G:$G,'Discounts Summary'!$C13)) | E13: =IF(SUMIFS('Order Level'!$O:$O,'Order Level'!$I:$I,"Delivered",'Order Level'!$G:$G,'Discounts Summary'!$C13)=0,"",SUMIFS('Order Level'!$O:$O,'Order Level'!$I:$I,"Delivered",'Order Level'!$G:$G,'Discounts Summary'!$C13)) | F13: =IF(SUMIF('Order Level'!$G:$G,$C13,'Order Level'!R:R)=0,"",SUMIF('Order Level'!$G:$G,$C13,'Order Level'!R:R)) | G13: =IFERROR(F13/D13,"") | H13: =IFERROR(F13/E13,"")
D14: =IF(COUNTIFS('Order Level'!$I:$I,"delivered",'Order Level'!$G:$G,'Discounts Summary'!$C14)=0,"",COUNTIFS('Order Level'!$I:$I,"delivered",'Order Level'!$G:$G,'Discounts Summary'!$C14)) | E14: =IF(SUMIFS('Order Level'!$O:$O,'Order Level'!$I:$I,"Delivered",'Order Level'!$G:$G,'Discounts Summary'!$C14)=0,"",SUMIFS('Order Level'!$O:$O,'Order Level'!$I:$I,"Delivered",'Order Level'!$G:$G,'Discounts Summary'!$C14)) | F14: =IF(SUMIF('Order Level'!$G:$G,$C14,'Order Level'!R:R)=0,"",SUMIF('Order Level'!$G:$G,$C14,'Order Level'!R:R)) | G14: =IFERROR(F14/D14,"") | H14: =IFERROR(F14/E14,"")
D15: =IF(COUNTIFS('Order Level'!$I:$I,"delivered",'Order Level'!$G:$G,'Discounts Summary'!$C15)=0,"",COUNTIFS('Order Level'!$I:$I,"delivered",'Order Level'!$G:$G,'Discounts Summary'!$C15)) | E15: =IF(SUMIFS('Order Level'!$O:$O,'Order Level'!$I:$I,"Delivered",'Order Level'!$G:$G,'Discounts Summary'!$C15)=0,"",SUMIFS('Order Level'!$O:$O,'Order Level'!$I:$I,"Delivered",'Order Level'!$G:$G,'Discounts Summary'!$C15)) | F15: =IF(SUMIF('Order Level'!$G:$G,$C15,'Order Level'!R:R)=0,"",SUMIF('Order Level'!$G:$G,$C15,'Order Level'!R:R)) | G15: =IFERROR(F15/D15,"") | H15: =IFERROR(F15/E15,"")
D16: =IF(COUNTIFS('Order Level'!$I:$I,"delivered",'Order Level'!$G:$G,'Discounts Summary'!$C16)=0,"",COUNTIFS('Order Level'!$I:$I,"delivered",'Order Level'!$G:$G,'Discounts Summary'!$C16)) | E16: =IF(SUMIFS('Order Level'!$O:$O,'Order Level'!$I:$I,"Delivered",'Order Level'!$G:$G,'Discounts Summary'!$C16)=0,"",SUMIFS('Order Level'!$O:$O,'Order Level'!$I:$I,"Delivered",'Order Level'!$G:$G,'Discounts Summary'!$C16)) | F16: =IF(SUMIF('Order Level'!$G:$G,$C16,'Order Level'!R:R)=0,"",SUMIF('Order Level'!$G:$G,$C16,'Order Level'!R:R)) | G16: =IFERROR(F16/D16,"") | H16: =IFERROR(F16/E16,"")
D17: =IF(COUNTIFS('Order Level'!$I:$I,"delivered",'Order Level'!$G:$G,'Discounts Summary'!$C17)=0,"",COUNTIFS('Order Level'!$I:$I,"delivered",'Order Level'!$G:$G,'Discounts Summary'!$C17)) | E17: =IF(SUMIFS('Order Level'!$O:$O,'Order Level'!$I:$I,"Delivered",'Order Level'!$G:$G,'Discounts Summary'!$C17)=0,"",SUMIFS('Order Level'!$O:$O,'Order Level'!$I:$I,"Delivered",'Order Level'!$G:$G,'Discounts Summary'!$C17)) | F17: =IF(SUMIF('Order Level'!$G:$G,$C17,'Order Level'!R:R)=0,"",SUMIF('Order Level'!$G:$G,$C17,'Order Level'!R:R)) | G17: =IFERROR(F17/D17,"") | H17: =IFERROR(F17/E17,"")
... D48: =IF(COUNTIFS('Order Level'!$I:$I,"delivered",'Order Level'!$G:$G,'Discounts Summary'!$C48)=0,"",COUNTIFS('Order Level'!$I:$I,"delivered",'Order Level'!$G:$G,'Discounts Summary'!$C48)) | E48: =IF(SUMIFS('Order Level'!$O:$O,'Order Level'!$I:$I,"Delivered",'Order Level'!$G:$G,'Discounts Summary'!$C48)=0,"",SUMIFS('Order Level'!$O:$O,'Order Level'!$I:$I,"Delivered",'Order Level'!$G:$G,'Discounts Summary'!$C48)) | F48: =IF(SUMIF('Order Level'!$G:$G,$C48,'Order Level'!R:R)=0,"",SUMIF('Order Level'!$G:$G,$C48,'Order Level'!R:R)) | G48: =IFERROR(F48/D48,"") | H48: =IFERROR(F48/E48,"")

Sheet Glossary
A1: Glossary
A2: =Summary!C30 -> Descriptions of the terms used in the Order Level tab
A3: S.No | B3: Particulars | C3: Definition
A4: 1 | B4: Subtotal (items total) | C4: Gross total of dishes/items ordered by the customer before discount
A5: 2 | B5: Packaging charge | C5: Cost set by the restaurant partner for the packaging material of whatever nature, including containers and coverings
A6: 3 | B6: Delivery charge for restaurants on self logistics | C6: Cost charged by restaurant partner when the delivery of order is undertaken by the restaurant partner themselves
A7: 4 | B7: Restaurant Discount [Promo] | C7: Offer or Promo discounts borne by the restaurant partner on the order
A8: 5 | B8: Restaurant discount [Flat offs, Freebies, Gold & others] | C8: PRO/SALT/ Freebie or any other discounts borne by the restaurant partner on the order
A9: 6 | B9: Brand pack subscription fee | C9: Revenue generated for the restaurant through brand pack subscriptions
A10: 7 | B10: Delivery charge discount | C10: Delivery charge discount borne by the resturant partner on the order
A11: 8 | B11: Total GST collected from customers | C11: Total tax amount paid by the customer on the order. It include GST on Food items, Packaging charges and delivery charges (for orders delivered by the restaurant partners themselves) after adjusting restaurant partner discount
A12: A | B12: Net order value | C12: This means the subtotal value received, including the packaging charge, Delivery Charge (for orders delivered by the restaurant partners themselves) and less restaurant partner discounts
A13: 9 | B13: Commissionable value (excluding customer GST) | C13: It is amount at which Zomato commission will be applied i.e. the total of Gross sales less delivery Charge (for orders delivered by restaurant partners themselves) and taxes
A14: 10 | B14: Service fee % | C14: This means the amount payable by the Restaurant Partner to Zomato, being a % of commissionable value
A15: 11 | B15: Service fee | C15: Derived value after multiplying commissionable value with base service fee %, However in case of flat fees contract like meal for one, total of individual items fixed fees will be the commission value.
A16: 12 | B16: Payment Mechanism Fee | C16: Payment Mechanism Fee means the amount payable by the Restaurant Partner to Zomato, being a % of Order Value including taxes less any charge not levied by Restaurant but collected by Zomato, as more specifically set out in the Form
A17: B | B17: Service fee & payment mechanism fees | C17: This is the sum of the base service fee, fulfilment fee, and payment mechanism fee, less
A18: 13 | B18: Applicable amount for TCS | C18: It is gross sales amount (less applicable taxes) on which Tax Collected at Source under CGST Act 2017. It is applicable on items other than supply of Restaurant Service.
A19: 14 | B19: Applicable amount for 9(5) | C19: It is gross sales amount (less applicable taxes) of items under Restaurant Service category as per Section 9(5) of Central Goods and Services Tax Act, 2017, with effect from 1 January 2022
A20: 15 | B20: Taxes on service & payment mechanism fees | C20: Tax charged on services provided by Zomato (such as commission, convenience fee etc)
A21: 16 | B21: Tax collected at source (TCS) | C21: TCS is amount collected at source by Zomato on items other than Restaurant Services in terms of provisions of Section 52 of the CGST Act, 2017. The said amount will be deposited to Government upon filing of TCS Return {GSTR-8} at GSTIN level.
A22: 17 | B22: TCS IGST amount | C22: If TCS mentioned in section R is deducted on interstate supply, same will be updated here
A23: 18 | B23: TDS 194O | C23: Zomato is required to deduct taxes at source from the amount for all Orders that are settled via Zomato’s Platform. TDS u/s 194-O shall be applied on Gross Sales (less applicable taxes charged by the Restaurant) as per the applicable tax law on the rate as applicable and amended from time to time
A24: 19 | B24: GST paid by Zomato on behalf of restaurant - under section 9(5) | C24: Tax amount retained by Zomato for restaurant services as per Section 9(5) of Central Goods and Services Tax Act 2017, with effect from 1 January 2022. Zomato deposits this tax amount with authorities on behalf of the restaurant
A25: 20 | B25: GST to be paid by Restaurant partner to Govt. | C25: This amount is residual value of total GST collected from user and deposited by Zomato under section 9(5) of GST Act. This amount need to deposited to Govt by Restaurant partners
A26: C | B26: Government charges | C26: Sum of all the taxes charged on the order as per the government guidelines
A27: 21 | B27: Customer Compensation/Recoupment | C27: The amount recovered/recouped against customer refunds made by Zomato, from the restaurant partners
A28: 22 | B28: Delivery charges recovery | C28: Amount of Discount offers by merchant on the delivery fee charged by the Delivery Partner, where the Restaurant Partner is availing Logistics Services from Zomato
A29: 23 | B29: Amount received in cash (on self delivery orders) | C29: Amount received by Restaurant partner from customer in cash on delivery order where Restaurant Partner provide logistics services
A30: 24 | B30: Credit note/(Debit Note) adjustment | C30: CN/DN raised to adjust commission/convenience fee or other revenue
A31: 25 | B31: Promo recovery adjustment | C31: Manual promo recovery to be done from restaurant partner where automated recovery were not made
A32: 26 | B32: Extra Inventory Ads (Order Level Deduction) | C32: The amount deducted against Extra inventory ads campaign
A33: D | B33: Other order-level deductions | C33: Sum of all deductions at an order level other than the service fee, payment mechanism fee, and government charges
A34: E | B34: Net Deductions | C34: Sum of all the recoveries which needs to be deducted from Restaurant Partner's payout
A35: F | B35: Net Additions (cancellation refund) | C35: Amount reimbursed against the rejected orders (Zomato rejections) under the compensation policy
A36: G | B36: Order level Payout | C36: Net transferable amount after all deductions
A37: 27 | B37: Settlement status | C37: The payment status of an order id i.e. "settled" means the payment for an order id is done while "pending" status means yet to be transferred.
A38: 28 | B38: Settlement date | C38: The date on which an order amount was transferred to partner's bank account
A39: 29 | B39: Bank UTR | C39: The transaction refernce number against which payments were transferred to the restaurant partner
A40: 30 | B40: Unsettled Amount | C40: The part of the order level payout which is pending to be settled

Sheet HSummary
E2: 01 Feb 2026 - 28 Feb 2026 | F2: 20523448 | G2: 92707 | H2: Manaswini Food Private Limited | I2: Purnabramha Aurangabad | J2: 1st floor,Pune, Aurangabad, Maharashtra | K2: AAKCM0381K | L2: 27AAKCM0381K1Z7 | N2: Weekly (Every Wednesday) | O2: 27AADCD4946L1CL | P2: 27AADCD4946L1ZA | S2: CITIN26625847955,CITIN26617354846,CITIN26620176758,CITIN26622782803,

Sheet HDiscount
